<?xml version="1.0" encoding="utf-8"?>
<robot name="go2_description">
  <link name="base_link">
    <inertial>
      <origin rpy="0 0 0" xyz="0.021112 0 -0.005366"></origin>
      <mass value="6.921"></mass>
      <inertia ixx="0.02448" ixy="0.00012166" ixz="0.0014849" iyy="0.098077" iyz="-3.12E-05" izz="0.107"></inertia>
    </inertial>
    <visual>
      <origin rpy="0 0 0" xyz="0 0 0"></origin>
      <geometry>
        <mesh filename="package://go2_description/dae/base.dae"></mesh>
      </geometry>
      <material name="黑色塑料_003-effect">
        <color rgba="0.023455 0.023455 0.023455 1"></color>
      </material>
    </visual>
    <collision>
      <origin rpy="0 0 0" xyz="0 0 0"></origin>
      <geometry>
        <box size="0.3762 0.0935 0.114"></box>
      </geometry>
    </collision>
  </link>
  <link name="Head_upper">
    <inertial>
      <origin rpy="0 0 0" xyz="0 0 0"></origin>
      <mass value="0.001"></mass>
      <inertia ixx="9.6e-06" ixy="0" ixz="0" iyy="9.6e-06" iyz="0" izz="9.6e-06"></inertia>
    </inertial>
    <collision>
      <origin rpy="0 0 0" xyz="0 0 0"></origin>
      <geometry>
        <cylinder length="0.09" radius="0.05"></cylinder>
      </geometry>
    </collision>
  </link>
  <joint dont_collapse="true" name="Head_upper_joint" type="fixed">
    <origin rpy="0 0 0" xyz="0.285 0 0.01"></origin>
    <parent link="base_link"></parent>
    <child link="Head_upper"></child>
    <axis xyz="0 0 0"></axis>
  </joint>
  <link name="Head_lower">
    <inertial>
      <origin rpy="0 0 0" xyz="0 0 0"></origin>
      <mass value="0.001"></mass>
      <inertia ixx="9.6e-06" ixy="0" ixz="0" iyy="9.6e-06" iyz="0" izz="9.6e-06"></inertia>
    </inertial>
    <collision>
      <origin rpy="0 0 0" xyz="0 0 0"></origin>
      <geometry>
        <sphere radius="0.047"></sphere>
      </geometry>
    </collision>
  </link>
  <joint dont_collapse="true" name="Head_lower_joint" type="fixed">
    <origin rpy="0 0 0" xyz="0.008 0 -0.07"></origin>
    <parent link="Head_upper"></parent>
    <child link="Head_lower"></child>
    <axis xyz="0 0 0"></axis>
  </joint>
  <link name="FL_hip">
    <inertial>
      <origin rpy="0 0 0" xyz="-0.0054 0.00194 -0.000105"></origin>
      <mass value="0.678"></mass>
      <inertia ixx="0.00048" ixy="-3.01E-06" ixz="1.11E-06" iyy="0.000884" iyz="-1.42E-06" izz="0.000596"></inertia>
    </inertial>
    <visual>
      <origin rpy="0 0 0" xyz="0 0 0"></origin>
      <geometry>
        <mesh filename="package://go2_description/dae/hip.dae"></mesh>
      </geometry>
      <material name="Material-effect">
        <color rgba="0.9 0.95 0.95 1"></color>
      </material>
    </visual>
    <collision>
      <origin rpy="1.5707963267948966 0 0" xyz="0 0.08 0"></origin>
      <geometry>
        <cylinder length="0.04" radius="0.046"></cylinder>
      </geometry>
    </collision>
  </link>
  <joint name="FL_hip_joint" type="revolute">
    <origin rpy="0 0 0" xyz="0.1934 0.0465 0"></origin>
    <parent link="base_link"></parent>
    <child link="FL_hip"></child>
    <axis xyz="1 0 0"></axis>
    <limit effort="23.7" lower="-1.0472" upper="1.0472" velocity="30.1"></limit>
  </joint>
  <link name="FL_hip_rotor">
    <inertial>
      <origin rpy="0 0 0" xyz="0.0 0.0 0.0"></origin>
      <mass value="0.089"></mass>
      <inertia ixx="0.000111842" ixy="0.0" ixz="0.0" iyy="0.000059647" iyz="0.0" izz="0.000059647"></inertia>
    </inertial>
  </link>
  <joint name="FL_hip_rotor_joint" type="fixed">
    <origin rpy="0 0 0" xyz="0.11215 0.04675 0"></origin>
    <parent link="base_link"></parent>
    <child link="FL_hip_rotor"></child>
  </joint>
  <link name="FL_thigh">
    <inertial>
      <origin rpy="0 0 0" xyz="-0.00374 -0.0223 -0.0327"></origin>
      <mass value="1.152"></mass>
      <inertia ixx="0.00584" ixy="8.72E-05" ixz="-0.000289" iyy="0.0058" iyz="0.000808" izz="0.00103"></inertia>
    </inertial>
    <visual>
      <origin rpy="0 0 0" xyz="0 0 0"></origin>
      <geometry>
        <mesh filename="package://go2_description/dae/thigh.dae"></mesh>
      </geometry>
      <material name="Material_009-effect">
        <color rgba="0.9 0.95 0.95 1"></color>
      </material>
    </visual>
    <collision>
      <origin rpy="0 1.5707963267948966 0" xyz="0 0 -0.1065"></origin>
      <geometry>
        <box size="0.213 0.0245 0.034"></box>
      </geometry>
    </collision>
  </link>
  <joint name="FL_thigh_joint" type="revolute">
    <origin rpy="0 0 0" xyz="0 0.0955 0"></origin>
    <parent link="FL_hip"></parent>
    <child link="FL_thigh"></child>
    <axis xyz="0 1 0"></axis>
    <limit effort="23.7" lower="-1.5708" upper="3.4907" velocity="30.1"></limit>
  </joint>
  <link name="FL_thigh_rotor">
    <inertial>
      <origin rpy="0 0 0" xyz="0.0 0.0 0.0"></origin>
      <mass value="0.089"></mass>
      <inertia ixx="0.000059647" ixy="0.0" ixz="0.0" iyy="0.000111842" iyz="0.0" izz="0.000059647"></inertia>
    </inertial>
  </link>
  <joint name="FL_thigh_rotor_joint" type="fixed">
    <origin rpy="0 0 0" xyz="0 -0.00015 0"></origin>
    <parent link="FL_hip"></parent>
    <child link="FL_thigh_rotor"></child>
  </joint>
  <link name="FL_calf">
    <inertial>
      <origin rpy="0 0 0" xyz="0.00548 -0.000975 -0.115"></origin>
      <mass value="0.154"></mass>
      <inertia ixx="0.00108" ixy="3.4E-07" ixz="1.72E-05" iyy="0.0011" iyz="8.28E-06" izz="3.29E-05"></inertia>
    </inertial>
    <visual>
      <origin rpy="0 0 0" xyz="0 0 0"></origin>
      <geometry>
        <mesh filename="package://go2_description/dae/calf.dae"></mesh>
      </geometry>
      <material name="深色橡胶_005-effect">
        <color rgba="0.6717055 0.6924257 0.7742702 1"></color>
      </material>
    </visual>
    <collision>
      <origin rpy="0 -0.21 0" xyz="0.008 0 -0.06"></origin>
      <geometry>
        <cylinder length="0.12" radius="0.012"></cylinder>
      </geometry>
    </collision>
  </link>
  <joint name="FL_calf_joint" type="revolute">
    <origin rpy="0 0 0" xyz="0 0 -0.213"></origin>
    <parent link="FL_thigh"></parent>
    <child link="FL_calf"></child>
    <axis xyz="0 1 0"></axis>
    <limit effort="45.43" lower="-2.7227" upper="-0.83776" velocity="15.70"></limit>
  </joint>
  <link name="FL_calflower">
    <collision>
      <origin rpy="0 0 0" xyz="0 0 0"></origin>
      <geometry>
        <cylinder length="0.065" radius="0.011"></cylinder>
      </geometry>
    </collision>
  </link>
  <joint name="FL_calflower_joint" type="fixed">
    <origin rpy="0 0.05 0" xyz="0.020 0 -0.148"></origin>
    <parent link="FL_calf"></parent>
    <child link="FL_calflower"></child>
    <axis xyz="0 0 0"></axis>
  </joint>
  <link name="FL_calflower1">
    <collision>
      <origin rpy="0 0 0" xyz="0 0 0"></origin>
      <geometry>
        <cylinder length="0.03" radius="0.0155"></cylinder>
      </geometry>
    </collision>
  </link>
  <joint name="FL_calflower1_joint" type="fixed">
    <origin rpy="0 0.48 0" xyz="-0.01 0 -0.04"></origin>
    <parent link="FL_calflower"></parent>
    <child link="FL_calflower1"></child>
    <axis xyz="0 0 0"></axis>
  </joint>
  <link name="FL_calf_rotor">
    <inertial>
      <origin rpy="0 0 0" xyz="0.0 0.0 0.0"></origin>
      <mass value="0.089"></mass>
      <inertia ixx="0.000059647" ixy="0.0" ixz="0.0" iyy="0.000111842" iyz="0.0" izz="0.000059647"></inertia>
    </inertial>
  </link>
  <joint name="FL_calf_rotor_joint" type="fixed">
    <origin rpy="0 0 0" xyz="0 -0.03235 0"></origin>
    <parent link="FL_thigh"></parent>
    <child link="FL_calf_rotor"></child>
  </joint>
  <link name="FL_foot">
    <inertial>
      <origin rpy="0 0 0" xyz="0 0 0"></origin>
      <mass value="0.04"></mass>
      <inertia ixx="9.6e-06" ixy="0" ixz="0" iyy="9.6e-06" iyz="0" izz="9.6e-06"></inertia>
    </inertial>
    <visual>
      <origin rpy="0 0 0" xyz="0 0 0"></origin>
      <geometry>
        <mesh filename="package://go2_description/dae/foot.dae"></mesh>
      </geometry>
      <material name="黑色足端_007-effect">
        <color rgba="0 0 0 1"></color>
      </material>
    </visual>
    <collision>
      <origin rpy="0 0 0" xyz="-0.002 0 0"></origin>
      <geometry>
        <sphere radius="0.022"></sphere>
      </geometry>
    </collision>
  </link>
  <joint dont_collapse="true" name="FL_foot_joint" type="fixed">
    <origin rpy="0 0 0" xyz="0 0 -0.213"></origin>
    <parent link="FL_calf"></parent>
    <child link="FL_foot"></child>
    <axis xyz="0 0 0"></axis>
  </joint>
  <link name="FR_hip">
    <inertial>
      <origin rpy="0 0 0" xyz="-0.0054 -0.00194 -0.000105"></origin>
      <mass value="0.678"></mass>
      <inertia ixx="0.00048" ixy="3.01E-06" ixz="1.11E-06" iyy="0.000884" iyz="1.42E-06" izz="0.000596"></inertia>
    </inertial>
    <visual>
      <origin rpy="3.1415 0 0" xyz="0 0 0"></origin>
      <geometry>
        <mesh filename="package://go2_description/dae/hip.dae"></mesh>
      </geometry>
      <material name="Material-effect">
        <color rgba="0.9 0.95 0.95 1"></color>
      </material>
    </visual>
    <collision>
      <origin rpy="1.5707963267948966 0 0" xyz="0 -0.08 0"></origin>
      <geometry>
        <cylinder length="0.04" radius="0.046"></cylinder>
      </geometry>
    </collision>
  </link>
  <joint name="FR_hip_joint" type="revolute">
    <origin rpy="0 0 0" xyz="0.1934 -0.0465 0"></origin>
    <parent link="base_link"></parent>
    <child link="FR_hip"></child>
    <axis xyz="1 0 0"></axis>
    <limit effort="23.7" lower="-1.0472" upper="1.0472" velocity="30.1"></limit>
  </joint>
  <link name="FR_hip_rotor">
    <inertial>
      <origin rpy="0 0 0" xyz="0.0 0.0 0.0"></origin>
      <mass value="0.089"></mass>
      <inertia ixx="0.000111842" ixy="0.0" ixz="0.0" iyy="0.000059647" iyz="0.0" izz="0.000059647"></inertia>
    </inertial>
  </link>
  <joint name="FR_hip_rotor_joint" type="fixed">
    <origin rpy="0 0 0" xyz="0.11215 -0.04675 0"></origin>
    <parent link="base_link"></parent>
    <child link="FR_hip_rotor"></child>
  </joint>
  <link name="FR_thigh">
    <inertial>
      <origin rpy="0 0 0" xyz="-0.00374 0.0223 -0.0327"></origin>
      <mass value="1.152"></mass>
      <inertia ixx="0.00584" ixy="-8.72E-05" ixz="-0.000289" iyy="0.0058" iyz="-0.000808" izz="0.00103"></inertia>
    </inertial>
    <visual>
      <origin rpy="0 0 0" xyz="0 0 0"></origin>
      <geometry>
        <mesh filename="package://go2_description/dae/thigh_mirror.dae"></mesh>
      </geometry>
      <material name="Material_011-effect">
        <color rgba="0.9 0.95 0.95 1"></color>
      </material>
    </visual>
    <collision>
      <origin rpy="0 1.5707963267948966 0" xyz="0 0 -0.1065"></origin>
      <geometry>
        <box size="0.213 0.0245 0.034"></box>
      </geometry>
    </collision>
  </link>
  <joint name="FR_thigh_joint" type="revolute">
    <origin rpy="0 0 0" xyz="0 -0.0955 0"></origin>
    <parent link="FR_hip"></parent>
    <child link="FR_thigh"></child>
    <axis xyz="0 1 0"></axis>
    <limit effort="23.7" lower="-1.5708" upper="3.4907" velocity="30.1"></limit>
  </joint>
  <link name="FR_thigh_rotor">
    <inertial>
      <origin rpy="0 0 0" xyz="0.0 0.0 0.0"></origin>
      <mass value="0.089"></mass>
      <inertia ixx="0.000059647" ixy="0.0" ixz="0.0" iyy="0.000111842" iyz="0.0" izz="0.000059647"></inertia>
    </inertial>
  </link>
  <joint name="FR_thigh_rotor_joint" type="fixed">
    <origin rpy="0 0 0" xyz="0 0.00015 0"></origin>
    <parent link="FR_hip"></parent>
    <child link="FR_thigh_rotor"></child>
  </joint>
  <link name="FR_calf">
    <inertial>
      <origin rpy="0 0 0" xyz="0.00548 0.000975 -0.115"></origin>
      <mass value="0.154"></mass>
      <inertia ixx="0.00108" ixy="-3.4E-07" ixz="1.72E-05" iyy="0.0011" iyz="-8.28E-06" izz="3.29E-05"></inertia>
    </inertial>
    <visual>
      <origin rpy="0 0 0" xyz="0 0 0"></origin>
      <geometry>
        <mesh filename="package://go2_description/dae/calf_mirror.dae"></mesh>
      </geometry>
      <material name="深色橡胶_007-effect">
        <color rgba="0.6717055 0.6924257 0.7742702 1"></color>
      </material>
    </visual>
    <collision>
      <origin rpy="0 -0.2 0" xyz="0.01 0 -0.06"></origin>
      <geometry>
        <cylinder length="0.12" radius="0.013"></cylinder>
      </geometry>
    </collision>
  </link>
  <joint name="FR_calf_joint" type="revolute">
    <origin rpy="0 0 0" xyz="0 0 -0.213"></origin>
    <parent link="FR_thigh"></parent>
    <child link="FR_calf"></child>
    <axis xyz="0 1 0"></axis>
    <limit effort="45.43" lower="-2.7227" upper="-0.83776" velocity="15.70"></limit>
  </joint>
  <link name="FR_calflower">
    <collision>
      <origin rpy="0 0 0" xyz="0 0 0"></origin>
      <geometry>
        <cylinder length="0.065" radius="0.011"></cylinder>
      </geometry>
    </collision>
  </link>
  <joint name="FR_calflower_joint" type="fixed">
    <origin rpy="0 0.05 0" xyz="0.020 0 -0.148"></origin>
    <parent link="FR_calf"></parent>
    <child link="FR_calflower"></child>
    <axis xyz="0 0 0"></axis>
  </joint>
  <link name="FR_calflower1">
    <collision>
      <origin rpy="0 0 0" xyz="0 0 0"></origin>
      <geometry>
        <cylinder length="0.03" radius="0.0155"></cylinder>
      </geometry>
    </collision>
  </link>
  <joint name="FR_calflower1_joint" type="fixed">
    <origin rpy="0 0.48 0" xyz="-0.01 0 -0.04"></origin>
    <parent link="FR_calflower"></parent>
    <child link="FR_calflower1"></child>
    <axis xyz="0 0 0"></axis>
  </joint>
  <link name="FR_calf_rotor">
    <inertial>
      <origin rpy="0 0 0" xyz="0.0 0.0 0.0"></origin>
      <mass value="0.089"></mass>
      <inertia ixx="0.000059647" ixy="0.0" ixz="0.0" iyy="0.000111842" iyz="0.0" izz="0.000059647"></inertia>
    </inertial>
  </link>
  <joint name="FR_calf_rotor_joint" type="fixed">
    <origin rpy="0 0 0" xyz="0 0.03235 0"></origin>
    <parent link="FR_thigh"></parent>
    <child link="FR_calf_rotor"></child>
  </joint>
  <link name="FR_foot">
    <inertial>
      <origin rpy="0 0 0" xyz="0 0 0"></origin>
      <mass value="0.04"></mass>
      <inertia ixx="9.6e-06" ixy="0" ixz="0" iyy="9.6e-06" iyz="0" izz="9.6e-06"></inertia>
    </inertial>
    <visual>
      <origin rpy="0 0 0" xyz="0 0 0"></origin>
      <geometry>
        <mesh filename="package://go2_description/dae/foot.dae"></mesh>
      </geometry>
      <material name="黑色足端_007-effect">
        <color rgba="0 0 0 1"></color>
      </material>
    </visual>
    <collision>
      <origin rpy="0 0 0" xyz="-0.002 0 0"></origin>
      <geometry>
        <sphere radius="0.022"></sphere>
      </geometry>
    </collision>
  </link>
  <joint dont_collapse="true" name="FR_foot_joint" type="fixed">
    <origin rpy="0 0 0" xyz="0 0 -0.213"></origin>
    <parent link="FR_calf"></parent>
    <child link="FR_foot"></child>
    <axis xyz="0 0 0"></axis>
  </joint>
  <link name="RL_hip">
    <inertial>
      <origin rpy="0 0 0" xyz="0.0054 0.00194 -0.000105"></origin>
      <mass value="0.678"></mass>
      <inertia ixx="0.00048" ixy="3.01E-06" ixz="-1.11E-06" iyy="0.000884" iyz="-1.42E-06" izz="0.000596"></inertia>
    </inertial>
    <visual>
      <origin rpy="0 3.1415 0" xyz="0 0 0"></origin>
      <geometry>
        <mesh filename="package://go2_description/dae/hip.dae"></mesh>
      </geometry>
      <material name="Material-effect">
        <color rgba="0.9 0.95 0.95 1"></color>
      </material>
    </visual>
    <collision>
      <origin rpy="1.5707963267948966 0 0" xyz="0 0.08 0"></origin>
      <geometry>
        <cylinder length="0.04" radius="0.046"></cylinder>
      </geometry>
    </collision>
  </link>
  <joint name="RL_hip_joint" type="revolute">
    <origin rpy="0 0 0" xyz="-0.1934 0.0465 0"></origin>
    <parent link="base_link"></parent>
    <child link="RL_hip"></child>
    <axis xyz="1 0 0"></axis>
    <limit effort="23.7" lower="-1.0472" upper="1.0472" velocity="30.1"></limit>
  </joint>
  <link name="RL_hip_rotor">
    <inertial>
      <origin rpy="0 0 0" xyz="0.0 0.0 0.0"></origin>
      <mass value="0.089"></mass>
      <inertia ixx="0.000111842" ixy="0.0" ixz="0.0" iyy="0.000059647" iyz="0.0" izz="0.000059647"></inertia>
    </inertial>
  </link>
  <joint name="RL_hip_rotor_joint" type="fixed">
    <origin rpy="0 0 0" xyz="-0.11215 0.04675 0"></origin>
    <parent link="base_link"></parent>
    <child link="RL_hip_rotor"></child>
  </joint>
  <link name="RL_thigh">
    <inertial>
      <origin rpy="0 0 0" xyz="-0.00374 -0.0223 -0.0327"></origin>
      <mass value="1.152"></mass>
      <inertia ixx="0.00584" ixy="8.72E-05" ixz="-0.000289" iyy="0.0058" iyz="0.000808" izz="0.00103"></inertia>
    </inertial>
    <visual>
      <origin rpy="0 0 0" xyz="0 0 0"></origin>
      <geometry>
        <mesh filename="package://go2_description/dae/thigh.dae"></mesh>
      </geometry>
      <material name="Material_009-effect">
        <color rgba="0.9 0.95 0.95 1"></color>
      </material>
    </visual>
    <collision>
      <origin rpy="0 1.5707963267948966 0" xyz="0 0 -0.1065"></origin>
      <geometry>
        <box size="0.213 0.0245 0.034"></box>
      </geometry>
    </collision>
  </link>
  <joint name="RL_thigh_joint" type="revolute">
    <origin rpy="0 0 0" xyz="0 0.0955 0"></origin>
    <parent link="RL_hip"></parent>
    <child link="RL_thigh"></child>
    <axis xyz="0 1 0"></axis>
    <limit effort="23.7" lower="-0.5236" upper="4.5379" velocity="30.1"></limit>
  </joint>
  <link name="RL_thigh_rotor">
    <inertial>
      <origin rpy="0 0 0" xyz="0.0 0.0 0.0"></origin>
      <mass value="0.089"></mass>
      <inertia ixx="0.000059647" ixy="0.0" ixz="0.0" iyy="0.000111842" iyz="0.0" izz="0.000059647"></inertia>
    </inertial>
  </link>
  <joint name="RL_thigh_rotor_joint" type="fixed">
    <origin rpy="0 0 0" xyz="0 -0.00015 0"></origin>
    <parent link="RL_hip"></parent>
    <child link="RL_thigh_rotor"></child>
  </joint>
  <link name="RL_calf">
    <inertial>
      <origin rpy="0 0 0" xyz="0.00548 -0.000975 -0.115"></origin>
      <mass value="0.154"></mass>
      <inertia ixx="0.00108" ixy="3.4E-07" ixz="1.72E-05" iyy="0.0011" iyz="8.28E-06" izz="3.29E-05"></inertia>
    </inertial>
    <visual>
      <origin rpy="0 0 0" xyz="0 0 0"></origin>
      <geometry>
        <mesh filename="package://go2_description/dae/calf.dae"></mesh>
      </geometry>
      <material name="深色橡胶_005-effect">
        <color rgba="0.6717055 0.6924257 0.7742702 1"></color>
      </material>
    </visual>
    <collision>
      <origin rpy="0 -0.2 0" xyz="0.01 0 -0.06"></origin>
      <geometry>
        <cylinder length="0.12" radius="0.013"></cylinder>
      </geometry>
    </collision>
  </link>
  <joint name="RL_calf_joint" type="revolute">
    <origin rpy="0 0 0" xyz="0 0 -0.213"></origin>
    <parent link="RL_thigh"></parent>
    <child link="RL_calf"></child>
    <axis xyz="0 1 0"></axis>
    <limit effort="45.43" lower="-2.7227" upper="-0.83776" velocity="15.70"></limit>
  </joint>
  <link name="RL_calflower">
    <collision>
      <origin rpy="0 0 0" xyz="0 0 0"></origin>
      <geometry>
        <cylinder length="0.065" radius="0.011"></cylinder>
      </geometry>
    </collision>
  </link>
  <joint name="RL_calflower_joint" type="fixed">
    <origin rpy="0 0.05 0" xyz="0.020 0 -0.148"></origin>
    <parent link="RL_calf"></parent>
    <child link="RL_calflower"></child>
    <axis xyz="0 0 0"></axis>
  </joint>
  <link name="RL_calflower1">
    <collision>
      <origin rpy="0 0 0" xyz="0 0 0"></origin>
      <geometry>
        <cylinder length="0.03" radius="0.0155"></cylinder>
      </geometry>
    </collision>
  </link>
  <joint name="RL_calflower1_joint" type="fixed">
    <origin rpy="0 0.48 0" xyz="-0.01 0 -0.04"></origin>
    <parent link="RL_calflower"></parent>
    <child link="RL_calflower1"></child>
    <axis xyz="0 0 0"></axis>
  </joint>
  <link name="RL_calf_rotor">
    <inertial>
      <origin rpy="0 0 0" xyz="0.0 0.0 0.0"></origin>
      <mass value="0.089"></mass>
      <inertia ixx="0.000059647" ixy="0.0" ixz="0.0" iyy="0.000111842" iyz="0.0" izz="0.000059647"></inertia>
    </inertial>
  </link>
  <joint name="RL_calf_rotor_joint" type="fixed">
    <origin rpy="0 0 0" xyz="0 -0.03235 0"></origin>
    <parent link="RL_thigh"></parent>
    <child link="RL_calf_rotor"></child>
  </joint>
  <link name="RL_foot">
    <inertial>
      <origin rpy="0 0 0" xyz="0 0 0"></origin>
      <mass value="0.04"></mass>
      <inertia ixx="9.6e-06" ixy="0" ixz="0" iyy="9.6e-06" iyz="0" izz="9.6e-06"></inertia>
    </inertial>
    <visual>
      <origin rpy="0 0 0" xyz="0 0 0"></origin>
      <geometry>
        <mesh filename="package://go2_description/dae/foot.dae"></mesh>
      </geometry>
      <material name="黑色足端_007-effect">
        <color rgba="0 0 0 1"></color>
      </material>
    </visual>
    <collision>
      <origin rpy="0 0 0" xyz="-0.002 0 0"></origin>
      <geometry>
        <sphere radius="0.022"></sphere>
      </geometry>
    </collision>
  </link>
  <joint dont_collapse="true" name="RL_foot_joint" type="fixed">
    <origin rpy="0 0 0" xyz="0 0 -0.213"></origin>
    <parent link="RL_calf"></parent>
    <child link="RL_foot"></child>
    <axis xyz="0 0 0"></axis>
  </joint>
  <link name="RR_hip">
    <inertial>
      <origin rpy="0 0 0" xyz="0.0054 -0.00194 -0.000105"></origin>
      <mass value="0.678"></mass>
      <inertia ixx="0.00048" ixy="-3.01E-06" ixz="-1.11E-06" iyy="0.000884" iyz="1.42E-06" izz="0.000596"></inertia>
    </inertial>
    <visual>
      <origin rpy="3.1415 3.1415 0" xyz="0 0 0"></origin>
      <geometry>
        <mesh filename="package://go2_description/dae/hip.dae"></mesh>
      </geometry>
      <material name="Material-effect">
        <color rgba="0.9 0.95 0.95 1"></color>
      </material>
    </visual>
    <collision>
      <origin rpy="1.5707963267948966 0 0" xyz="0 -0.08 0"></origin>
      <geometry>
        <cylinder length="0.04" radius="0.046"></cylinder>
      </geometry>
    </collision>
  </link>
  <joint name="RR_hip_joint" type="revolute">
    <origin rpy="0 0 0" xyz="-0.1934 -0.0465 0"></origin>
    <parent link="base_link"></parent>
    <child link="RR_hip"></child>
    <axis xyz="1 0 0"></axis>
    <limit effort="23.7" lower="-1.0472" upper="1.0472" velocity="30.1"></limit>
  </joint>
  <link name="RR_hip_rotor">
    <inertial>
      <origin rpy="0 0 0" xyz="0.0 0.0 0.0"></origin>
      <mass value="0.089"></mass>
      <inertia ixx="0.000111842" ixy="0.0" ixz="0.0" iyy="0.000059647" iyz="0.0" izz="0.000059647"></inertia>
    </inertial>
  </link>
  <joint name="RR_hip_rotor_joint" type="fixed">
    <origin rpy="0 0 0" xyz="-0.11215 -0.04675 0"></origin>
    <parent link="base_link"></parent>
    <child link="RR_hip_rotor"></child>
  </joint>
  <link name="RR_thigh">
    <inertial>
      <origin rpy="0 0 0" xyz="-0.00374 0.0223 -0.0327"></origin>
      <mass value="1.152"></mass>
      <inertia ixx="0.00584" ixy="-8.72E-05" ixz="-0.000289" iyy="0.0058" iyz="-0.000808" izz="0.00103"></inertia>
    </inertial>
    <visual>
      <origin rpy="0 0 0" xyz="0 0 0"></origin>
      <geometry>
        <mesh filename="package://go2_description/dae/thigh_mirror.dae"></mesh>
      </geometry>
      <material name="Material_011-effect">
        <color rgba="0.9 0.95 0.95 1"></color>
      </material>
    </visual>
    <collision>
      <origin rpy="0 1.5707963267948966 0" xyz="0 0 -0.1065"></origin>
      <geometry>
        <box size="0.213 0.0245 0.034"></box>
      </geometry>
    </collision>
  </link>
  <joint name="RR_thigh_joint" type="revolute">
    <origin rpy="0 0 0" xyz="0 -0.0955 0"></origin>
    <parent link="RR_hip"></parent>
    <child link="RR_thigh"></child>
    <axis xyz="0 1 0"></axis>
    <limit effort="23.7" lower="-0.5236" upper="4.5379" velocity="30.1"></limit>
  </joint>
  <link name="RR_thigh_rotor">
    <inertial>
      <origin rpy="0 0 0" xyz="0.0 0.0 0.0"></origin>
      <mass value="0.089"></mass>
      <inertia ixx="0.000059647" ixy="0.0" ixz="0.0" iyy="0.000111842" iyz="0.0" izz="0.000059647"></inertia>
    </inertial>
  </link>
  <joint name="RR_thigh_rotor_joint" type="fixed">
    <origin rpy="0 0 0" xyz="0 0.00015 0"></origin>
    <parent link="RR_hip"></parent>
    <child link="RR_thigh_rotor"></child>
  </joint>
  <link name="RR_calf">
    <inertial>
      <origin rpy="0 0 0" xyz="0.00548 0.000975 -0.115"></origin>
      <mass value="0.154"></mass>
      <inertia ixx="0.00108" ixy="-3.4E-07" ixz="1.72E-05" iyy="0.0011" iyz="-8.28E-06" izz="3.29E-05"></inertia>
    </inertial>
    <visual>
      <origin rpy="0 0 0" xyz="0 0 0"></origin>
      <geometry>
        <mesh filename="package://go2_description/dae/calf_mirror.dae"></mesh>
      </geometry>
      <material name="深色橡胶_007-effect">
        <color rgba="0.6717055 0.6924257 0.7742702 1"></color>
      </material>
    </visual>
    <collision>
      <origin rpy="0 -0.2 0" xyz="0.01 0 -0.06"></origin>
      <geometry>
        <cylinder length="0.12" radius="0.013"></cylinder>
      </geometry>
    </collision>
  </link>
  <joint name="RR_calf_joint" type="revolute">
    <origin rpy="0 0 0" xyz="0 0 -0.213"></origin>
    <parent link="RR_thigh"></parent>
    <child link="RR_calf"></child>
    <axis xyz="0 1 0"></axis>
    <limit effort="45.43" lower="-2.7227" upper="-0.83776" velocity="15.70"></limit>
  </joint>
  <link name="RR_calflower">
    <collision>
      <origin rpy="0 0 0" xyz="0 0 0"></origin>
      <geometry>
        <cylinder length="0.065" radius="0.011"></cylinder>
      </geometry>
    </collision>
  </link>
  <joint name="RR_calflower_joint" type="fixed">
    <origin rpy="0 0.05 0" xyz="0.020 0 -0.148"></origin>
    <parent link="RR_calf"></parent>
    <child link="RR_calflower"></child>
    <axis xyz="0 0 0"></axis>
  </joint>
  <link name="RR_calflower1">
    <collision>
      <origin rpy="0 0 0" xyz="0 0 0"></origin>
      <geometry>
        <cylinder length="0.03" radius="0.0155"></cylinder>
      </geometry>
    </collision>
  </link>
  <joint name="RR_calflower1_joint" type="fixed">
    <origin rpy="0 0.48 0" xyz="-0.01 0 -0.04"></origin>
    <parent link="RR_calflower"></parent>
    <child link="RR_calflower1"></child>
    <axis xyz="0 0 0"></axis>
  </joint>
  <link name="RR_calf_rotor">
    <inertial>
      <origin rpy="0 0 0" xyz="0.0 0.0 0.0"></origin>
      <mass value="0.089"></mass>
      <inertia ixx="0.000059647" ixy="0.0" ixz="0.0" iyy="0.000111842" iyz="0.0" izz="0.000059647"></inertia>
    </inertial>
  </link>
  <joint name="RR_calf_rotor_joint" type="fixed">
    <origin rpy="0 0 0" xyz="0 0.03235 0"></origin>
    <parent link="RR_thigh"></parent>
    <child link="RR_calf_rotor"></child>
  </joint>
  <link name="RR_foot">
    <inertial>
      <origin rpy="0 0 0" xyz="0 0 0"></origin>
      <mass value="0.04"></mass>
      <inertia ixx="9.6e-06" ixy="0" ixz="0" iyy="9.6e-06" iyz="0" izz="9.6e-06"></inertia>
    </inertial>
    <visual>
      <origin rpy="0 0 0" xyz="0 0 0"></origin>
      <geometry>
        <mesh filename="package://go2_description/dae/foot.dae"></mesh>
      </geometry>
      <material name="黑色足端_007-effect">
        <color rgba="0 0 0 1"></color>
      </material>
    </visual>
    <collision>
      <origin rpy="0 0 0" xyz="-0.002 0 0"></origin>
      <geometry>
        <sphere radius="0.022"></sphere>
      </geometry>
    </collision>
  </link>
  <joint dont_collapse="true" name="RR_foot_joint" type="fixed">
    <origin rpy="0 0 0" xyz="0 0 -0.213"></origin>
    <parent link="RR_calf"></parent>
    <child link="RR_foot"></child>
    <axis xyz="0 0 0"></axis>
  </joint>
  <link name="imu">
    <inertial>
      <origin rpy="0 0 0" xyz="0 0 0"></origin>
      <mass value="0"></mass>
      <inertia ixx="0" ixy="0" ixz="0" iyy="0" iyz="0" izz="0"></inertia>
    </inertial>
  </link>
  <joint name="imu_joint" type="fixed">
    <origin rpy="0 0 0" xyz="-0.02557 0 0.04232"></origin>
    <parent link="base_link"></parent>
    <child link="imu"></child>
    <axis xyz="0 0 0"></axis>
  </joint>
  <link name="radar">
    <inertial>
      <origin rpy="0 0 0" xyz="0 0 0"></origin>
      <mass value="0"></mass>
      <inertia ixx="0" ixy="0" ixz="0" iyy="0" iyz="0" izz="0"></inertia>
    </inertial>
  </link>
  <joint name="radar_joint" type="fixed">
    <origin rpy="0 2.8782 0" xyz="0.28945 0 -0.046825"></origin>
    <parent link="base_link"></parent>
    <child link="radar"></child>
    <axis xyz="0 0 0"></axis>
  </joint>
  <joint name="front_camera_joint" type="fixed">
    <origin rpy="0 0 0" xyz="0.32715 -0.00003 0.04297"></origin>
    <parent link="base_link"></parent>
    <child link="front_camera"></child>
  </joint>
  <link name="front_camera"></link>
</robot>

